<?xml version="1.0" encoding="UTF-8"?>
<testng-results skipped="0" failed="4" total="7" passed="3">
  <reporter-output>
  </reporter-output>
  <suite name="Suite" duration-ms="1346" started-at="2019-09-27T04:37:54Z" finished-at="2019-09-27T04:37:55Z">
    <groups>
      <group name="smokeTests">
        <method signature="TestBusinessIds.getBusinessesById()[pri:0, instance:com.business.testCases.TestBusinessIds@5f375618]" name="getBusinessesById" class="com.business.testCases.TestBusinessIds"/>
        <method signature="TestBusinesses.getBusinesses()[pri:0, instance:com.business.testCases.TestBusinesses@396a51ab]" name="getBusinesses" class="com.business.testCases.TestBusinesses"/>
        <method signature="TestSummarySales.getSummarySales()[pri:0, instance:com.summarySales.testCases.TestSummarySales@51081592]" name="getSummarySales" class="com.summarySales.testCases.TestSummarySales"/>
      </group> <!-- smokeTests -->
      <group name="negativeTests">
        <method signature="TestBusinessIds.getBusinessesByIncorrectURL()[pri:0, instance:com.business.testCases.TestBusinessIds@5f375618]" name="getBusinessesByIncorrectURL" class="com.business.testCases.TestBusinessIds"/>
        <method signature="TestBusinessIds.getBusinessesByNonExistingIds()[pri:0, instance:com.business.testCases.TestBusinessIds@5f375618]" name="getBusinessesByNonExistingIds" class="com.business.testCases.TestBusinessIds"/>
        <method signature="TestBusinesses.getBusinessesByIncorrectURL()[pri:0, instance:com.business.testCases.TestBusinesses@396a51ab]" name="getBusinessesByIncorrectURL" class="com.business.testCases.TestBusinesses"/>
        <method signature="TestSummarySales.getSummarySalesByIncorrectURL()[pri:0, instance:com.summarySales.testCases.TestSummarySales@51081592]" name="getSummarySalesByIncorrectURL" class="com.summarySales.testCases.TestSummarySales"/>
      </group> <!-- negativeTests -->
    </groups>
    <test name="Test" duration-ms="1346" started-at="2019-09-27T04:37:54Z" finished-at="2019-09-27T04:37:55Z">
      <class name="com.business.testCases.TestBusinesses">
        <test-method status="PASS" signature="setup()[pri:0, instance:com.business.testCases.TestBusinesses@396a51ab]" name="setup" is-config="true" duration-ms="2" started-at="2019-09-26T22:37:55Z" finished-at="2019-09-26T22:37:55Z">
          <reporter-output>
          </reporter-output>
        </test-method> <!-- setup -->
        <test-method status="PASS" signature="getBusinesses()[pri:0, instance:com.business.testCases.TestBusinesses@396a51ab]" name="getBusinesses" duration-ms="272" started-at="2019-09-26T22:37:55Z" finished-at="2019-09-26T22:37:55Z">
          <reporter-output>
          </reporter-output>
        </test-method> <!-- getBusinesses -->
        <test-method status="FAIL" signature="getBusinessesByIncorrectURL()[pri:0, instance:com.business.testCases.TestBusinesses@396a51ab]" name="getBusinessesByIncorrectURL" duration-ms="13" started-at="2019-09-26T22:37:55Z" finished-at="2019-09-26T22:37:55Z">
          <exception class="java.lang.AssertionError">
            <message>
              <![CDATA[expected [404] but found [200]]]>
            </message>
            <full-stacktrace>
              <![CDATA[java.lang.AssertionError: expected [404] but found [200]
	at org.testng.Assert.fail(Assert.java:94)
	at org.testng.Assert.failNotEquals(Assert.java:494)
	at org.testng.Assert.assertEquals(Assert.java:123)
	at org.testng.Assert.assertEquals(Assert.java:370)
	at org.testng.Assert.assertEquals(Assert.java:380)
	at com.business.testCases.TestBusinesses.getBusinessesByIncorrectURL(TestBusinesses.java:125)
	at sun.reflect.NativeMethodAccessorImpl.invoke0(Native Method)
	at sun.reflect.NativeMethodAccessorImpl.invoke(NativeMethodAccessorImpl.java:62)
	at sun.reflect.DelegatingMethodAccessorImpl.invoke(DelegatingMethodAccessorImpl.java:43)
	at java.lang.reflect.Method.invoke(Method.java:498)
	at org.testng.internal.MethodInvocationHelper.invokeMethod(MethodInvocationHelper.java:80)
	at org.testng.internal.Invoker.invokeMethod(Invoker.java:714)
	at org.testng.internal.Invoker.invokeTestMethod(Invoker.java:901)
	at org.testng.internal.Invoker.invokeTestMethods(Invoker.java:1231)
	at org.testng.internal.TestMethodWorker.invokeTestMethods(TestMethodWorker.java:127)
	at org.testng.internal.TestMethodWorker.run(TestMethodWorker.java:111)
	at org.testng.TestRunner.privateRun(TestRunner.java:767)
	at org.testng.TestRunner.run(TestRunner.java:617)
	at org.testng.SuiteRunner.runTest(SuiteRunner.java:334)
	at org.testng.SuiteRunner.runSequentially(SuiteRunner.java:329)
	at org.testng.SuiteRunner.privateRun(SuiteRunner.java:291)
	at org.testng.SuiteRunner.run(SuiteRunner.java:240)
	at org.testng.SuiteRunnerWorker.runSuite(SuiteRunnerWorker.java:52)
	at org.testng.SuiteRunnerWorker.run(SuiteRunnerWorker.java:86)
	at org.testng.TestNG.runSuitesSequentially(TestNG.java:1198)
	at org.testng.TestNG.runSuitesLocally(TestNG.java:1123)
	at org.testng.TestNG.run(TestNG.java:1031)
	at org.testng.remote.AbstractRemoteTestNG.run(AbstractRemoteTestNG.java:126)
	at org.testng.remote.RemoteTestNG.initAndRun(RemoteTestNG.java:137)
	at org.testng.remote.RemoteTestNG.main(RemoteTestNG.java:58)
]]>
            </full-stacktrace>
          </exception> <!-- java.lang.AssertionError -->
          <reporter-output>
          </reporter-output>
        </test-method> <!-- getBusinessesByIncorrectURL -->
      </class> <!-- com.business.testCases.TestBusinesses -->
      <class name="com.summarySales.testCases.TestSummarySales">
        <test-method status="PASS" signature="setup()[pri:0, instance:com.summarySales.testCases.TestSummarySales@51081592]" name="setup" is-config="true" duration-ms="1" started-at="2019-09-26T22:37:55Z" finished-at="2019-09-26T22:37:55Z">
          <reporter-output>
          </reporter-output>
        </test-method> <!-- setup -->
        <test-method status="PASS" signature="getSummarySales()[pri:0, instance:com.summarySales.testCases.TestSummarySales@51081592]" name="getSummarySales" duration-ms="45" started-at="2019-09-26T22:37:55Z" finished-at="2019-09-26T22:37:55Z">
          <reporter-output>
          </reporter-output>
        </test-method> <!-- getSummarySales -->
        <test-method status="FAIL" signature="getSummarySalesByIncorrectURL()[pri:0, instance:com.summarySales.testCases.TestSummarySales@51081592]" name="getSummarySalesByIncorrectURL" duration-ms="11" started-at="2019-09-26T22:37:55Z" finished-at="2019-09-26T22:37:55Z">
          <exception class="java.lang.AssertionError">
            <message>
              <![CDATA[expected [404] but found [200]]]>
            </message>
            <full-stacktrace>
              <![CDATA[java.lang.AssertionError: expected [404] but found [200]
	at org.testng.Assert.fail(Assert.java:94)
	at org.testng.Assert.failNotEquals(Assert.java:494)
	at org.testng.Assert.assertEquals(Assert.java:123)
	at org.testng.Assert.assertEquals(Assert.java:370)
	at org.testng.Assert.assertEquals(Assert.java:380)
	at com.summarySales.testCases.TestSummarySales.getSummarySalesByIncorrectURL(TestSummarySales.java:135)
	at sun.reflect.NativeMethodAccessorImpl.invoke0(Native Method)
	at sun.reflect.NativeMethodAccessorImpl.invoke(NativeMethodAccessorImpl.java:62)
	at sun.reflect.DelegatingMethodAccessorImpl.invoke(DelegatingMethodAccessorImpl.java:43)
	at java.lang.reflect.Method.invoke(Method.java:498)
	at org.testng.internal.MethodInvocationHelper.invokeMethod(MethodInvocationHelper.java:80)
	at org.testng.internal.Invoker.invokeMethod(Invoker.java:714)
	at org.testng.internal.Invoker.invokeTestMethod(Invoker.java:901)
	at org.testng.internal.Invoker.invokeTestMethods(Invoker.java:1231)
	at org.testng.internal.TestMethodWorker.invokeTestMethods(TestMethodWorker.java:127)
	at org.testng.internal.TestMethodWorker.run(TestMethodWorker.java:111)
	at org.testng.TestRunner.privateRun(TestRunner.java:767)
	at org.testng.TestRunner.run(TestRunner.java:617)
	at org.testng.SuiteRunner.runTest(SuiteRunner.java:334)
	at org.testng.SuiteRunner.runSequentially(SuiteRunner.java:329)
	at org.testng.SuiteRunner.privateRun(SuiteRunner.java:291)
	at org.testng.SuiteRunner.run(SuiteRunner.java:240)
	at org.testng.SuiteRunnerWorker.runSuite(SuiteRunnerWorker.java:52)
	at org.testng.SuiteRunnerWorker.run(SuiteRunnerWorker.java:86)
	at org.testng.TestNG.runSuitesSequentially(TestNG.java:1198)
	at org.testng.TestNG.runSuitesLocally(TestNG.java:1123)
	at org.testng.TestNG.run(TestNG.java:1031)
	at org.testng.remote.AbstractRemoteTestNG.run(AbstractRemoteTestNG.java:126)
	at org.testng.remote.RemoteTestNG.initAndRun(RemoteTestNG.java:137)
	at org.testng.remote.RemoteTestNG.main(RemoteTestNG.java:58)
]]>
            </full-stacktrace>
          </exception> <!-- java.lang.AssertionError -->
          <reporter-output>
          </reporter-output>
        </test-method> <!-- getSummarySalesByIncorrectURL -->
      </class> <!-- com.summarySales.testCases.TestSummarySales -->
      <class name="com.business.testCases.TestBusinessIds">
        <test-method status="PASS" signature="setup()[pri:0, instance:com.business.testCases.TestBusinessIds@5f375618]" name="setup" is-config="true" duration-ms="56" started-at="2019-09-26T22:37:54Z" finished-at="2019-09-26T22:37:54Z">
          <reporter-output>
          </reporter-output>
        </test-method> <!-- setup -->
        <test-method status="PASS" signature="getBusinessesById()[pri:0, instance:com.business.testCases.TestBusinessIds@5f375618]" name="getBusinessesById" duration-ms="901" started-at="2019-09-26T22:37:54Z" finished-at="2019-09-26T22:37:55Z">
          <reporter-output>
          </reporter-output>
        </test-method> <!-- getBusinessesById -->
        <test-method status="FAIL" signature="getBusinessesByIncorrectURL()[pri:0, instance:com.business.testCases.TestBusinessIds@5f375618]" name="getBusinessesByIncorrectURL" duration-ms="14" started-at="2019-09-26T22:37:55Z" finished-at="2019-09-26T22:37:55Z">
          <exception class="java.lang.AssertionError">
            <message>
              <![CDATA[expected [404] but found [200]]]>
            </message>
            <full-stacktrace>
              <![CDATA[java.lang.AssertionError: expected [404] but found [200]
	at org.testng.Assert.fail(Assert.java:94)
	at org.testng.Assert.failNotEquals(Assert.java:494)
	at org.testng.Assert.assertEquals(Assert.java:123)
	at org.testng.Assert.assertEquals(Assert.java:370)
	at org.testng.Assert.assertEquals(Assert.java:380)
	at com.business.testCases.TestBusinessIds.getBusinessesByIncorrectURL(TestBusinessIds.java:153)
	at sun.reflect.NativeMethodAccessorImpl.invoke0(Native Method)
	at sun.reflect.NativeMethodAccessorImpl.invoke(NativeMethodAccessorImpl.java:62)
	at sun.reflect.DelegatingMethodAccessorImpl.invoke(DelegatingMethodAccessorImpl.java:43)
	at java.lang.reflect.Method.invoke(Method.java:498)
	at org.testng.internal.MethodInvocationHelper.invokeMethod(MethodInvocationHelper.java:80)
	at org.testng.internal.Invoker.invokeMethod(Invoker.java:714)
	at org.testng.internal.Invoker.invokeTestMethod(Invoker.java:901)
	at org.testng.internal.Invoker.invokeTestMethods(Invoker.java:1231)
	at org.testng.internal.TestMethodWorker.invokeTestMethods(TestMethodWorker.java:127)
	at org.testng.internal.TestMethodWorker.run(TestMethodWorker.java:111)
	at org.testng.TestRunner.privateRun(TestRunner.java:767)
	at org.testng.TestRunner.run(TestRunner.java:617)
	at org.testng.SuiteRunner.runTest(SuiteRunner.java:334)
	at org.testng.SuiteRunner.runSequentially(SuiteRunner.java:329)
	at org.testng.SuiteRunner.privateRun(SuiteRunner.java:291)
	at org.testng.SuiteRunner.run(SuiteRunner.java:240)
	at org.testng.SuiteRunnerWorker.runSuite(SuiteRunnerWorker.java:52)
	at org.testng.SuiteRunnerWorker.run(SuiteRunnerWorker.java:86)
	at org.testng.TestNG.runSuitesSequentially(TestNG.java:1198)
	at org.testng.TestNG.runSuitesLocally(TestNG.java:1123)
	at org.testng.TestNG.run(TestNG.java:1031)
	at org.testng.remote.AbstractRemoteTestNG.run(AbstractRemoteTestNG.java:126)
	at org.testng.remote.RemoteTestNG.initAndRun(RemoteTestNG.java:137)
	at org.testng.remote.RemoteTestNG.main(RemoteTestNG.java:58)
]]>
            </full-stacktrace>
          </exception> <!-- java.lang.AssertionError -->
          <reporter-output>
          </reporter-output>
        </test-method> <!-- getBusinessesByIncorrectURL -->
        <test-method status="FAIL" signature="getBusinessesByNonExistingIds()[pri:0, instance:com.business.testCases.TestBusinessIds@5f375618]" name="getBusinessesByNonExistingIds" duration-ms="14" started-at="2019-09-26T22:37:55Z" finished-at="2019-09-26T22:37:55Z">
          <exception class="java.lang.AssertionError">
            <message>
              <![CDATA[expected [400] but found [200]]]>
            </message>
            <full-stacktrace>
              <![CDATA[java.lang.AssertionError: expected [400] but found [200]
	at org.testng.Assert.fail(Assert.java:94)
	at org.testng.Assert.failNotEquals(Assert.java:494)
	at org.testng.Assert.assertEquals(Assert.java:123)
	at org.testng.Assert.assertEquals(Assert.java:370)
	at org.testng.Assert.assertEquals(Assert.java:380)
	at com.business.testCases.TestBusinessIds.getBusinessesByNonExistingIds(TestBusinessIds.java:118)
	at sun.reflect.NativeMethodAccessorImpl.invoke0(Native Method)
	at sun.reflect.NativeMethodAccessorImpl.invoke(NativeMethodAccessorImpl.java:62)
	at sun.reflect.DelegatingMethodAccessorImpl.invoke(DelegatingMethodAccessorImpl.java:43)
	at java.lang.reflect.Method.invoke(Method.java:498)
	at org.testng.internal.MethodInvocationHelper.invokeMethod(MethodInvocationHelper.java:80)
	at org.testng.internal.Invoker.invokeMethod(Invoker.java:714)
	at org.testng.internal.Invoker.invokeTestMethod(Invoker.java:901)
	at org.testng.internal.Invoker.invokeTestMethods(Invoker.java:1231)
	at org.testng.internal.TestMethodWorker.invokeTestMethods(TestMethodWorker.java:127)
	at org.testng.internal.TestMethodWorker.run(TestMethodWorker.java:111)
	at org.testng.TestRunner.privateRun(TestRunner.java:767)
	at org.testng.TestRunner.run(TestRunner.java:617)
	at org.testng.SuiteRunner.runTest(SuiteRunner.java:334)
	at org.testng.SuiteRunner.runSequentially(SuiteRunner.java:329)
	at org.testng.SuiteRunner.privateRun(SuiteRunner.java:291)
	at org.testng.SuiteRunner.run(SuiteRunner.java:240)
	at org.testng.SuiteRunnerWorker.runSuite(SuiteRunnerWorker.java:52)
	at org.testng.SuiteRunnerWorker.run(SuiteRunnerWorker.java:86)
	at org.testng.TestNG.runSuitesSequentially(TestNG.java:1198)
	at org.testng.TestNG.runSuitesLocally(TestNG.java:1123)
	at org.testng.TestNG.run(TestNG.java:1031)
	at org.testng.remote.AbstractRemoteTestNG.run(AbstractRemoteTestNG.java:126)
	at org.testng.remote.RemoteTestNG.initAndRun(RemoteTestNG.java:137)
	at org.testng.remote.RemoteTestNG.main(RemoteTestNG.java:58)
]]>
            </full-stacktrace>
          </exception> <!-- java.lang.AssertionError -->
          <reporter-output>
          </reporter-output>
        </test-method> <!-- getBusinessesByNonExistingIds -->
      </class> <!-- com.business.testCases.TestBusinessIds -->
    </test> <!-- Test -->
  </suite> <!-- Suite -->
</testng-results>
